<mujocoinclude>
  <!--
  Franka Panda robot for Metaworld (replacement for Sawyer xyz_base)
  
  Usage:
  <mujoco>
      <include file="../objects/panda_dependencies.xml"/>
      <include file="../scene/basic_scene.xml"/>
      <worldbody>
          <include file="../objects/panda.xml"/>
      </worldbody>
      <actuator>
          <position ctrllimited="true" ctrlrange="-1 1" joint="r_close" kp="400" user="1"/>
          <position ctrllimited="true" ctrlrange="-1 1" joint="l_close" kp="400" user="1"/>
      </actuator>
      <equality>
          <weld body1="mocap" body2="hand" solref="0.02 1"></weld>
      </equality>
  </mujoco>
  -->

  <camera pos="0 0.5 1.5" name="topview" />
  <camera name="corner" mode="fixed" pos="-1.1 -0.4 0.6" xyaxes="-1 1 0 -0.2 -0.2 -1"/>
  <camera name="corner2" fovy="60" mode="fixed" pos="1.3 -0.2 1.1" euler="3.9 2.3 0.6"/>
  <camera name="corner3" fovy="45" mode="fixed" pos="0.9 0 1.5" euler="3.5 2.7 1"/>
  <camera name="corner4" fovy="60" mode="fixed" pos="0.75 0.075 0.7" euler="3.9 2.3 0.6"/>

  <body name="base" childclass="panda" pos="0 0 0">
    <site name="basesite" pos="0 0 0" size="0.01" />
    <inertial pos="0 0 0" mass="0" diaginertia="0 0 0" />
    
    <!-- Pedestal/base structure similar to Sawyer -->
    <body name="controller_box" pos="0 0 0">
      <inertial pos="-0.325 0 -0.38" mass="46.64" diaginertia="1.71363 1.27988 0.809981" />
      <geom size="0.11 0.2 0.265" pos="-0.325 0 -0.38" type="box" rgba="0.2 0.2 0.2 1"/>
    </body>
    <body name="pedestal_feet" pos="0 0 0">
      <inertial pos="-0.1225 0 -0.758" mass="167.09" diaginertia="8.16095 9.59375 15.0785" />
      <geom size="0.385 0.35 0.155" pos="-0.1225 0 -0.758" type="box" rgba="0.2 0.2 0.2 1"
            contype="0" conaffinity="0"/>
    </body>
    <body name="torso" pos="0 0 0">
      <inertial pos="0 0 0" mass="0.0001" diaginertia="1e-08 1e-08 1e-08" />
      <geom size="0.05 0.05 0.05" type="box" contype="0" conaffinity="0" group="1" rgba="0.2 0.2 0.2 1" />
    </body>
    <body name="pedestal" pos="0 0 0">
      <inertial pos="0 0 0" quat="0.659267 -0.259505 -0.260945 0.655692" mass="60.864" diaginertia="6.0869 5.81635 4.20915" />
      <geom pos="0 0 -0.29" type="cylinder" size="0.18 0.31" rgba="0.2 0.2 0.2 1" contype="0" conaffinity="0"/>
    </body>
    
    <!-- Panda Link 0 (base) -->
    <body name="link0" pos="0 0 0">
      <inertial mass="0.629769" pos="-0.041018 -0.00014 0.049974"
        fullinertia="0.00315 0.00388 0.004285 8.2904e-7 0.00015 8.2299e-6"/>
      <geom mesh="link0_c" class="collision"/>
      <geom mesh="link0_0" material="off_white" class="visual"/>
      <geom mesh="link0_1" material="black" class="visual"/>
      <geom mesh="link0_2" material="off_white" class="visual"/>
      <geom mesh="link0_3" material="black" class="visual"/>
      <geom mesh="link0_4" material="off_white" class="visual"/>
      <geom mesh="link0_5" material="black" class="visual"/>
      <geom mesh="link0_7" material="white" class="visual"/>
      <geom mesh="link0_8" material="white" class="visual"/>
      <geom mesh="link0_9" material="black" class="visual"/>
      <geom mesh="link0_10" material="off_white" class="visual"/>
      <geom mesh="link0_11" material="white" class="visual"/>
      
      <!-- Panda Link 1 -->
      <body name="link1" pos="0 0 0.333">
        <inertial mass="4.970684" pos="0.003875 0.002081 -0.04762"
          fullinertia="0.70337 0.70661 0.0091170 -0.00013900 0.0067720 0.019169"/>
        <joint name="panda_joint1" pos="0 0 0" axis="0 0 1" limited="true" range="-2.8973 2.8973" damping="10"/>
        <geom material="white" mesh="link1" class="visual"/>
        <geom mesh="link1_c" class="collision"/>
        
        <!-- Panda Link 2 -->
        <body name="link2" quat="1 -1 0 0">
          <inertial mass="0.646926" pos="-0.003141 -0.02872 0.003495"
            fullinertia="0.0079620 2.8110e-2 2.5995e-2 -3.925e-3 1.0254e-2 7.04e-4"/>
          <joint name="panda_joint2" pos="0 0 0" axis="0 0 1" limited="true" range="-1.7628 1.7628" damping="10"/>
          <geom material="white" mesh="link2" class="visual"/>
          <geom mesh="link2_c" class="collision"/>
          
          <!-- Panda Link 3 -->
          <body name="link3" pos="0 -0.316 0" quat="1 1 0 0">
            <inertial mass="3.228604" pos="2.7518e-2 3.9252e-2 -6.6502e-2"
              fullinertia="3.7242e-2 3.6155e-2 1.083e-2 -4.761e-3 -1.1396e-2 -1.2805e-2"/>
            <joint name="panda_joint3" pos="0 0 0" axis="0 0 1" limited="true" range="-2.8973 2.8973" damping="10"/>
            <geom mesh="link3_0" material="white" class="visual"/>
            <geom mesh="link3_1" material="white" class="visual"/>
            <geom mesh="link3_2" material="white" class="visual"/>
            <geom mesh="link3_3" material="black" class="visual"/>
            <geom mesh="link3_c" class="collision"/>
            
            <!-- Panda Link 4 -->
            <body name="link4" pos="0.0825 0 0" quat="1 1 0 0">
              <inertial mass="3.587895" pos="-5.317e-2 1.04419e-1 2.      7454e-2" fullinertia="2.5853e-2 1.9552e-2 2.8323e-2 7.796e-3 -1.332e-3 8.641e-3"/>
              <joint name="joint4" range="-3.0718 -0.0698"/>
              <geom mesh="link4_0" material="white" class="visual"/>
              <geom mesh="link4_1" material="white" class="visual"/>
              <geom mesh="link4_2" material="black" class="visual"/>
              <geom mesh="link4_3" material="white" class="visual"/>
              <geom mesh="link4_c" class="collision"/>
              
              <!-- Panda Link 5 -->
              <body name="link5" pos="-0.0825 0.384 0" quat="1 -1 0 0">
                <inertial mass="1.225946" pos="-1.1953e-2 4.1065e-2 -3.8437e-2"
                  fullinertia="3.5549e-2 2.9474e-2 8.627e-3 -2.117e-3 -4.037e-3 2.29e-4"/>
                <joint name="panda_joint5" pos="0 0 0" axis="0 0 1" limited="true" range="-2.8973 2.8973" damping="10"/>
                <geom mesh="link5_0" material="black" class="visual"/>
                <geom mesh="link5_1" material="white" class="visual"/>
                <geom mesh="link5_2" material="white" class="visual"/>
                <geom mesh="link5_c0" class="collision"/>
                <geom mesh="link5_c1" class="collision"/>
                <geom mesh="link5_c2" class="collision"/>
                
                <!-- Panda Link 6 -->
                <body name="link6" quat="1 1 0 0">
                  <inertial mass="1.666555" pos="6.0149e-2 -1.4117e-2 -1.0517e-2"
                    fullinertia="1.964e-3 4.354e-3 5.433e-3 1.09e-4 -1.158e-3 3.41e-4"/>
                  <joint name="panda_joint6" pos="0 0 0" axis="0 0 1" limited="true" range="-0.0175 3.7525" damping="10"/>
                  <geom mesh="link6_0" material="off_white" class="visual"/>
                  <geom mesh="link6_1" material="white" class="visual"/>
                  <geom mesh="link6_2" material="black" class="visual"/>
                  <geom mesh="link6_3" material="white" class="visual"/>
                  <geom mesh="link6_4" material="white" class="visual"/>
                  <geom mesh="link6_5" material="white" class="visual"/>
                  <geom mesh="link6_6" material="white" class="visual"/>
                  <geom mesh="link6_7" material="light_blue" class="visual"/>
                  <geom mesh="link6_8" material="light_blue" class="visual"/>
                  <geom mesh="link6_9" material="black" class="visual"/>
                  <geom mesh="link6_10" material="black" class="visual"/>
                  <geom mesh="link6_11" material="white" class="visual"/>
                  <geom mesh="link6_12" material="green" class="visual"/>
                  <geom mesh="link6_13" material="white" class="visual"/>
                  <geom mesh="link6_14" material="black" class="visual"/>
                  <geom mesh="link6_15" material="black" class="visual"/>
                  <geom mesh="link6_16" material="white" class="visual"/>
                  <geom mesh="link6_c" class="collision"/>
                  
                  <!-- Panda Link 7 -->
                  <body name="link7" pos="0.088 0 0" quat="1 1 0 0">
                    <inertial mass="7.35522e-01" pos="1.0517e-2 -4.252e-3 6.1597e-2"
                      fullinertia="1.2516e-2 1.0027e-2 4.815e-3 -4.28e-4 -1.196e-3 -7.41e-4"/>
                    <joint name="panda_joint7" pos="0 0 0" axis="0 0 1" limited="true" range="-2.8973 2.8973" damping="10"/>
                    <geom mesh="link7_0" material="white" class="visual"/>
                    <geom mesh="link7_1" material="black" class="visual"/>
                    <geom mesh="link7_2" material="black" class="visual"/>
                    <geom mesh="link7_3" material="black" class="visual"/>
                    <geom mesh="link7_4" material="black" class="visual"/>
                    <geom mesh="link7_5" material="black" class="visual"/>
                    <geom mesh="link7_6" material="black" class="visual"/>
                    <geom mesh="link7_7" material="white" class="visual"/>
                    <geom mesh="link7_c" class="collision"/>
                    
                    <!-- Panda Hand (gripper mount) - Named "hand" for Metaworld compatibility -->
                    <body name="hand" pos="0 0 0.107" quat="0.9238795 0 0 -0.3826834">
                      <inertial mass="0.73" pos="-0.01 0 0.03" diaginertia="0.001 0.0025 0.0017"/>
                      <geom mesh="hand_0" material="off_white" class="visual"/>
                      <geom mesh="hand_1" material="black" class="visual"/>
                      <geom mesh="hand_2" material="black" class="visual"/>
                      <geom mesh="hand_3" material="white" class="visual"/>
                      <geom mesh="hand_4" material="off_white" class="visual"/>
                      <geom mesh="hand_c" class="collision"/>
                      
                      <!-- Gripper body (compatible with Metaworld) -->
                      <body name="gripper_base" pos="0 0 0.12" quat="-1 0 1 0">
                        <camera name="behindGripper" mode="track" pos="0 0 -0.5" quat="0 1 0 0" fovy="60" />
                        <camera name="gripperPOV" mode="track" pos="0.04 -0.06 0" quat="-1 -1.3 0 0" fovy="90" />
                        
                        <site name="endEffector" pos="0.04 0 0" size="0.01" rgba='1 1 1 0' />
                        <geom name="rail" type="box" pos="-0.05 0 0" density="7850" size="0.005 0.055 0.005" rgba="0.5 0.5 0.5 1.0" condim="3" friction="2 0.1 0.002"/>
                        
                        <!-- Right finger/claw -->
                        <body name="rightclaw" pos="0 -0.05 0">
                          <geom class="base_col" name="rightclaw_it" condim="4" margin="0.001" type="box" user="0" pos="0 0 0" size="0.045 0.003 0.015" rgba="1 1 1 1.0"/>
                          <joint name="r_close" pos="0 0 0" axis="0 1 0" range="0 0.04" armature="100" damping="1000" limited="true" type="slide"/>
                          <site name="rightEndEffector" pos="0.045 0 0" size="0.01" rgba="1.0 0.0 0.0 1.0"/>
                          
                          <body name="rightpad" pos="0 .003 0">
                            <geom name="rightpad_geom" condim="4" margin="0.001" type="box" user="0" pos="0 0 0" size="0.045 0.003 0.015" rgba="1 1 1 1.0" solimp="0.95 0.99 0.01" solref="0.01 1" friction="2 0.1 0.002" contype="1" conaffinity="1" mass="1"/>
                          </body>
                        </body>
                        
                        <!-- Left finger/claw -->
                        <body name="leftclaw" pos="0 0.05 0">
                          <geom class="base_col" name="leftclaw_it" condim="4" margin="0.001" type="box" user="0" pos="0 0 0" size="0.045 0.003 0.015" rgba="0 1 1 1.0"/>
                          <joint name="l_close" pos="0 0 0" axis="0 1 0" range="-0.03 0" armature="100" damping="1000" limited="true" type="slide"/>
                          <site name="leftEndEffector" pos="0.045 0 0" size="0.01" rgba="1.0 0.0 0.0 1.0"/>
                          
                          <body name="leftpad" pos="0 -.003 0">
                            <geom name="leftpad_geom" condim="4" margin="0.001" type="box" user="0" pos="0 0 0" size="0.045 0.003 0.015" rgba="0 1 1 1.0" solimp="0.95 0.99 0.01" solref="0.01 1" friction="2 0.1 0.002" contype="1" conaffinity="1"/>
                          </body>
                        </body>
                      </body>
                    </body>
                  </body>
                </body>
              </body>
            </body>
          </body>
        </body>
      </body>
    </body>
  </body>
  
  <!-- Mocap body for control (used by weld constraint) -->
  <body mocap="true" name="mocap" pos="0 0 0">
    <geom conaffinity="0" contype="0" pos="0 0 0" rgba="0.0 0.5 0.5 0" size="0.01" type="sphere"/>
    <site name="mocap" pos="0 0 0" rgba="0.0 0.5 0.5 0" size="0.01" type="sphere"/>
  </body>

</mujocoinclude>
