<mujocoinclude>

  <camera pos="0 0.5 1.5" name="topview" />
  <camera name="corner" mode="fixed" pos="-1.1 -0.4 0.6" xyaxes="-1 1 0 -0.2 -0.2 -1"/>
  <camera name="corner2" fovy="60" mode="fixed" pos="1.3 -0.2 1.1" euler="3.9 2.3 0.6"/>
  <camera name="corner3" fovy="45" mode="fixed" pos="0.9 0 1.5" euler="3.5 2.7 1"/>
  <camera name="corner4" fovy="60" mode="fixed" pos="0.75 0.075 0.7" euler="3.9 2.3 0.6"/>

  <body name="ur10e_base" childclass="ur10e" pos="0 0 0">
    <site name="basesite" pos="0 0 0" size="0.01" />
    <inertial pos="0 0 0" mass="0" diaginertia="0 0 0" />
    <body name="controller_box" pos="0 0 0">
      <inertial pos="-0.325 0 -0.38" mass="46.64" diaginertia="1.71363 1.27988 0.809981" />
      <geom size="0.11 0.2 0.265" pos="-0.325 0 -0.38" type="box" rgba="0.2 0.2 0.2 1"/>
    </body>
    <body name="pedestal_feet" pos="0 0 0">
      <inertial pos="-0.1225 0 -0.758" mass="167.09" diaginertia="8.16095 9.59375 15.0785" />
      <geom size="0.385 0.35 0.155" pos="-0.1225 0 -0.758" type="box" rgba="0.2 0.2 0.2 1"
            contype="0" conaffinity="0"/>
    </body>
    <body name="torso" pos="0 0 0">
      <inertial pos="0 0 0" mass="0.0001" diaginertia="1e-08 1e-08 1e-08" />
      <geom size="0.05 0.05 0.05" type="box" contype="0" conaffinity="0" group="1" rgba="0.2 0.2 0.2 1" />
    </body>
    <body name="pedestal" pos="0 0 0">
      <inertial pos="0 0 0" quat="0.659267 -0.259505 -0.260945 0.655692" mass="60.864" diaginertia="6.0869 5.81635 4.20915" />
      <geom pos="0 0 -0.29" type="cylinder" size="0.18 0.31" rgba="0.2 0.2 0.2 1" contype="0" conaffinity="0"/>
    </body>

    <body name="ur10e_link0" quat="0 0 0 -1" childclass="ur10e">
      <inertial mass="4.0" pos="0 0 0" diaginertia="0.0061063308908 0.0061063308908 0.01125"/>
      <geom mesh="base_0" material="black" class="visual"/>
      <geom mesh="base_1" material="jointgray" class="visual"/>
      <body name="shoulder_link" pos="0 0 0.181">
        <inertial pos="0 0 0" mass="7.778" diaginertia="0.0314743 0.0314743 0.0218756"/>
        <joint name="shoulder_pan_joint" class="size4" axis="0 0 1"/>
        <geom mesh="shoulder_0" material="urblue" class="visual"/>
        <geom mesh="shoulder_1" material="black" class="visual"/>
        <geom mesh="shoulder_2" material="jointgray" class="visual"/>
        <geom class="collision" size="0.078 0.08" pos="0 0 -0.05"/>
        <body name="upper_arm_link" pos="0 0.176 0" quat="1 0 1 0">
          <inertial pos="0 0 0.3065" mass="12.93" diaginertia="0.423074 0.423074 0.0363656"/>
          <joint name="shoulder_lift_joint" class="size4"/>
          <geom mesh="upperarm_0" material="black" class="visual"/>
          <geom mesh="upperarm_1" material="jointgray" class="visual"/>
          <geom mesh="upperarm_2" material="urblue" class="visual"/>
          <geom mesh="upperarm_3" material="linkgray" class="visual"/>
          <geom class="collision" pos="0 -0.05 0" quat="1 1 0 0" size="0.078 0.08"/>
          <geom class="collision" size="0.06 0.3" pos="0 0 0.3"/>
          <body name="forearm_link" pos="0 -0.137 0.613">
            <inertial pos="0 0 0.2855" mass="3.87" diaginertia="0.11059 0.11059 0.0108844"/>
            <joint name="elbow_joint" class="size3_limited"/>
            <geom mesh="forearm_0" material="urblue" class="visual"/>
            <geom mesh="forearm_1" material="black" class="visual"/>
            <geom mesh="forearm_2" material="jointgray" class="visual"/>
            <geom mesh="forearm_3" material="linkgray" class="visual"/>
            <geom class="collision" pos="0 0.08 0" quat="1 1 0 0" size="0.058 0.065"/>
            <geom class="collision" size="0.043 0.28" pos="0 0 0.29"/>
            <body name="wrist_1_link" pos="0 0 0.571" quat="1 0 1 0">
              <inertial pos="0 0.135 0" quat="0.5 0.5 -0.5 0.5" mass="1.96"
                diaginertia="0.0055125 0.00510825 0.00510825"/>
              <joint name="wrist_1_joint" class="size2"/>
              <geom mesh="wrist1_0" material="black" class="visual"/>
              <geom mesh="wrist1_1" material="urblue" class="visual"/>
              <geom mesh="wrist1_2" material="jointgray" class="visual"/>
              <geom class="collision" pos="0 0.06 0" quat="1 1 0 0" size="0.05 0.07"/>
              <body name="wrist_2_link" pos="0 0.135 0">
                <inertial pos="0 0 0.12" quat="0.5 0.5 -0.5 0.5" mass="1.96"
                  diaginertia="0.0055125 0.00510825 0.00510825"/>
                <joint name="wrist_2_joint" axis="0 0 1" class="size2"/>
                <geom mesh="wrist2_0" material="black" class="visual"/>
                <geom mesh="wrist2_1" material="urblue" class="visual"/>
                <geom mesh="wrist2_2" material="jointgray" class="visual"/>
                <geom class="collision" size="0.046 0.065" pos="0 0 0.05"/>
                <geom class="collision" pos="0 0.028 0.12" quat="1 1 0 0" size="0.046 0.043"/>
                <body name="wrist_3_link" pos="0 0 0.12">
                  <inertial pos="0 0.092 0" quat="0 1 -1 0" mass="0.202"
                    diaginertia="0.000204525 0.000144346 0.000144346"/>
                  <joint name="wrist_3_joint" class="size2"/>
                  <geom material="linkgray" mesh="wrist3" class="visual"/>
                  <geom class="eef_collision" pos="0 0.097 0" quat="1 1 0 0" size="0.046 0.02"/>
                  <site name="attachment_site" pos="0 0.1 0" quat="-1 1 0 0"/>

                  

                  <!-- Hand -->
                  <body name="base_mount" pos="0 0.1 0" quat="-1 1 0 0" childclass="2f85">
                    <camera name="behindGripper" mode="track" pos="0 0 -0.5" quat="0 1 0 0" fovy="60"/>
                    <camera name="gripperPOV" mode="track" pos="0.04 -0.06 0" quat="-1 -1.3 0 0" fovy="90"/>

                    <site name="endEffector" pos="0 0 0.1034" size="0.01" rgba="1 1 1 0"/>

                    <geom class="2f85_visual" mesh="base_mount" material="black"/>
                    <geom class="2f85_collision" mesh="base_mount"/>
                    <body name="base" pos="0 0 0.0038" quat="1 0 0 -1">
                        <inertial mass="0.777441" pos="0 -2.70394e-05 0.0354675" quat="1 -0.00152849 0 0"
                        diaginertia="0.000260285 0.000225381 0.000152708"/>
                        <geom class="2f85_visual" mesh="base" material="black"/>
                        <geom class="2f85_collision" mesh="base"/>
                        <site name="pinch" pos="0 0 0.145" type="sphere" group="5" rgba="0.9 0.9 0.9 1" size="0.005"/>
                        <!-- Right-hand side 4-bar linkage -->
                        <body name="right_driver" pos="0 0.0306011 0.054904">
                            <inertial mass="0.00899563" pos="2.96931e-12 0.0177547 0.00107314" quat="0.681301 0.732003 0 0"
                                diaginertia="1.72352e-06 1.60906e-06 3.22006e-07"/>
                            <joint name="right_driver_joint" class="driver"/>
                            <geom class="2f85_visual" mesh="driver" material="gray"/>
                            <geom class="2f85_collision" mesh="driver"/>
                            <body name="right_coupler" pos="0 0.0315 -0.0041">
                                <inertial mass="0.0140974" pos="0 0.00301209 0.0232175" quat="0.705636 -0.0455904 0.0455904 0.705636"
                                diaginertia="4.16206e-06 3.52216e-06 8.88131e-07"/>
                                <joint name="right_coupler_joint" class="coupler"/>
                                <geom class="2f85_visual" mesh="coupler" material="black"/>
                                <geom class="2f85_collision" mesh="coupler"/>
                            </body>
                        </body>
                        <body name="right_spring_link" pos="0 0.0132 0.0609">
                            <inertial mass="0.0221642" pos="-8.65005e-09 0.0181624 0.0212658" quat="0.663403 -0.244737 0.244737 0.663403"
                                diaginertia="8.96853e-06 6.71733e-06 2.63931e-06"/>
                            <joint name="right_spring_link_joint" class="spring_link"/>
                            <geom class="2f85_visual" mesh="spring_link" material="black"/>
                            <geom class="2f85_collision" mesh="spring_link"/>
                            <body name="right_follower" pos="0 0.055 0.0375">
                                <inertial mass="0.0125222" pos="0 -0.011046 0.0124786" quat="1 0.1664 0 0"
                                diaginertia="2.67415e-06 2.4559e-06 6.02031e-07"/>
                                <joint name="right_follower_joint" class="follower"/>
                                <geom class="2f85_visual" mesh="follower" material="black"/>
                                <geom class="2f85_collision" mesh="follower"/>
                                <body name="right_pad" pos="0 -0.0189 0.01352">
                                <geom class="pad_box1" name="right_pad1"/>
                                <geom class="pad_box2" name="right_pad2"/>
                                <inertial mass="0.0035" pos="0 -0.0025 0.0185" quat="0.707107 0 0 0.707107"
                                    diaginertia="4.73958e-07 3.64583e-07 1.23958e-07"/>
                                <geom class="2f85_visual" mesh="pad"/>
                                <body name="right_silicone_pad">
                                    <geom class="2f85_visual" mesh="silicone_pad" material="black"/>
                                </body>
                                </body>
                            </body>
                        </body>
                        <!-- Left-hand side 4-bar linkage -->
                        <body name="left_driver" pos="0 -0.0306011 0.054904" quat="0 0 0 1">
                            <inertial mass="0.00899563" pos="0 0.0177547 0.00107314" quat="0.681301 0.732003 0 0"
                                diaginertia="1.72352e-06 1.60906e-06 3.22006e-07"/>
                            <joint name="left_driver_joint" class="driver"/>
                            <geom class="2f85_visual" mesh="driver" material="gray"/>
                            <geom class="2f85_collision" mesh="driver"/>
                            <body name="left_coupler" pos="0 0.0315 -0.0041">
                                <inertial mass="0.0140974" pos="0 0.00301209 0.0232175" quat="0.705636 -0.0455904 0.0455904 0.705636"
                                diaginertia="4.16206e-06 3.52216e-06 8.88131e-07"/>
                                <joint name="left_coupler_joint" class="coupler"/>
                                <geom class="2f85_visual" mesh="coupler" material="black"/>
                                <geom class="2f85_collision" mesh="coupler"/>
                            </body>
                        </body>
                        <body name="left_spring_link" pos="0 -0.0132 0.0609" quat="0 0 0 1">
                            <inertial mass="0.0221642" pos="-8.65005e-09 0.0181624 0.0212658" quat="0.663403 -0.244737 0.244737 0.663403"
                                diaginertia="8.96853e-06 6.71733e-06 2.63931e-06"/>
                            <joint name="left_spring_link_joint" class="spring_link"/>
                            <geom class="2f85_visual" mesh="spring_link" material="black"/>
                            <geom class="2f85_collision" mesh="spring_link"/>
                            <body name="left_follower" pos="0 0.055 0.0375">
                                <inertial mass="0.0125222" pos="0 -0.011046 0.0124786" quat="1 0.1664 0 0"
                                diaginertia="2.67415e-06 2.4559e-06 6.02031e-07"/>
                                <joint name="left_follower_joint" class="follower"/>
                                <geom class="2f85_visual" mesh="follower" material="black"/>
                                <geom class="2f85_collision" mesh="follower"/>
                                <body name="left_pad" pos="0 -0.0189 0.01352">
                                    <geom class="pad_box1" name="left_pad1"/>
                                    <geom class="pad_box2" name="left_pad2"/>
                                    <inertial mass="0.0035" pos="0 -0.0025 0.0185" quat="1 0 0 1"
                                        diaginertia="4.73958e-07 3.64583e-07 1.23958e-07"/>
                                    <geom class="2f85_visual" mesh="pad"/>
                                    <body name="left_silicone_pad">
                                        <geom class="2f85_visual" mesh="silicone_pad" material="black"/>
                                    </body>
                                </body>
                            </body>
                        </body>
                    </body>
                  </body>
                </body>
              </body>
            </body>
          </body>
        </body>
      </body>
    </body>
  </body>

  <body mocap="true" name="mocap" pos="0 0 0">
      <geom conaffinity="0" contype="0" pos="0 0 0" rgba="0.0 0.5 0.5 0" size="0.01" type="sphere"/>
      <site name="mocap" pos="0 0 0" rgba="0.0 0.5 0.5 0" size="0.01" type="sphere"/>
  </body>


</mujocoinclude>